Workbook

Sheet VARIABLE_DICTIONARY
A1: Variable ID | B1: Tên biến (Tiếng Việt) | C1: Tên biến (English) | D1: Loại dữ liệu | E1: Đơn vị | F1: Nhập bởi ai? | G1: Công thức / Quy tắc | H1: Output?
A2: P1 | B2: Sản lượng năm 1 | C2: Production year 1 | D2: Input | E2: Đơn vị sản phẩm | F2: Người dùng / nguồn dữ liệu | G2: — | H2: Không
A3: P2 | B3: Sản lượng năm 2 | C3: Production year 2 | D3: Input | E3: Đơn vị sản phẩm | F3: Người dùng / nguồn dữ liệu | G3: — | H3: Không
A4: P3 | B4: Sản lượng năm 3 | C4: Production year 3 | D4: Input | E4: Đơn vị sản phẩm | F4: Người dùng / nguồn dữ liệu | G4: — | H4: Không
A5: E1 | B5: Phát thải năm 1 | C5: Emissions year 1 | D5: Input | E5: tCO2e | F5: Người dùng / nguồn dữ liệu | G5: — | H5: Không
A6: E2 | B6: Phát thải năm 2 | C6: Emissions year 2 | D6: Input | E6: tCO2e | F6: Người dùng / nguồn dữ liệu | G6: — | H6: Không
A7: E3 | B7: Phát thải năm 3 | C7: Emissions year 3 | D7: Input | E7: tCO2e | F7: Người dùng / nguồn dữ liệu | G7: — | H7: Không
A8: P_avg | B8: Sản lượng trung bình ba năm y-1, y-2, y-3 | C8: Average production over y-1, y-2, y-3 | D8: Calculated | E8: Đơn vị sản phẩm | F8: Hệ thống | G8: (P_y-1 + P_y-2 + P_y-3) / 3 | H8: Có
A9: E_avg | B9: Phát thải trung bình ba năm y-1, y-2, y-3 | C9: Average emissions over y-1, y-2, y-3 | D9: Calculated | E9: tCO2e | F9: Hệ thống | G9: (E_y-1 + E_y-2 + E_y-3) / 3 | H9: Có
A10: B | B10: Lượng phát thải KNK trung bình trên một đơn vị sản phẩm của lĩnh vực | C10: Sector benchmark / average GHG emissions per product unit | D10: Calculated | E10: tCO2e / đơn vị sản phẩm | F10: Hệ thống | G10: ΣE_avg / ΣP_avg | H10: Có
A11: g | B11: Mục tiêu tăng trưởng của lĩnh vực | C11: Sector growth target | D11: Policy parameter | E11: % | F11: Bộ quản lý lĩnh vực / nguồn chính sách | G11: Tham số trong công thức T; giá trị thực tế chưa nhập | H11: Không
A12: r | B12: Mục tiêu giảm phát thải KNK của lĩnh vực | C12: Sector GHG reduction target | D12: Policy parameter | E12: % | F12: Bộ quản lý lĩnh vực / nguồn chính sách | G12: Tham số trong công thức T; giá trị thực tế chưa nhập | H12: Không
... A14: A | B14: Hạn ngạch phát thải KNK tính toán cho cơ sở | C14: Calculated GHG allowance | D14: Calculated | E14: tCO2e | F14: Hệ thống | G14: P_avg × B × T | H14: Có

Sheet FACILITIES
A1: Facility ID | B1: Facility Name | C1: Sector | D1: Product | E1: Product Unit | F1: Tax ID | G1: Inventory status used for 2025-2026 allocation basis | H1: Official Allocation 2025 (tCO2e) | I1: Official Allocation 2026 (tCO2e) | J1: Allocation Legal Source | K1: Data Status | L1: Notes
A2: =OFFICIAL_ALLOCATIONS!A2 -> F001 | B2: Công ty nhiệt điện Na Dương | D2: Electricity | E2: kWh | F2: 0104297034-001 | G2: YES — facility was within the inventory-list scope used for 2025-2026 quota allocation | H2: 1035566 | I2: 1134493 | J2: Decision 699/QĐ-BNNMT | K2: Official | L2: Do not use this field to infer current post-25/09/2026 inventory-list membership; check the effective list separately.
A3: =OFFICIAL_ALLOCATIONS!A3 -> F002 | B3: Công ty nhiệt điện Sơn động Việt Nam | D3: Electricity | E3: kWh | F3: 0104297034-003 | G3: YES — facility was within the inventory-list scope used for 2025-2026 quota allocation | H3: 2032458 | I3: 2226618 | J3: Decision 699/QĐ-BNNMT | K3: Official | L3: Do not use this field to infer current post-25/09/2026 inventory-list membership; check the effective list separately.
A4: =OFFICIAL_ALLOCATIONS!A4 -> F003 | B4: Công ty Nhiệt điện Uông Bí | D4: Electricity | E4: kWh | F4: 5701662152-010 | G4: YES — facility was within the inventory-list scope used for 2025-2026 quota allocation | H4: 5691098 | I4: 6234766 | J4: Decision 699/QĐ-BNNMT | K4: Official | L4: Do not use this field to infer current post-25/09/2026 inventory-list membership; check the effective list separately.
A5: =OFFICIAL_ALLOCATIONS!A5 -> F004 | B5: Công ty Cổ phần Nhiệt điện Quảng Ninh | D5: Electricity | E5: kWh | F5: 5700434869 | G5: YES — facility was within the inventory-list scope used for 2025-2026 quota allocation | H5: 11097421 | I5: 12157553 | J5: Decision 699/QĐ-BNNMT | K5: Official | L5: Do not use this field to infer current post-25/09/2026 inventory-list membership; check the effective list separately.
A6: =OFFICIAL_ALLOCATIONS!A6 -> F005 | B6: Công ty Nhiệt điện Cẩm Phả - TKV | D6: Electricity | E6: kWh | F6: 0104297034-008 | G6: YES — facility was within the inventory-list scope used for 2025-2026 quota allocation | H6: 3585092 | I6: 3927575 | J6: Decision 699/QĐ-BNNMT | K6: Official | L6: Do not use this field to infer current post-25/09/2026 inventory-list membership; check the effective list separately.
A7: =OFFICIAL_ALLOCATIONS!A7 -> F006 | B7: Công ty TNHH Điện Lực AES Mông Dương - Nhà máy nhiệt điện Mông Dương II | D7: Electricity | E7: kWh | F7: 5701384498 | G7: YES — facility was within the inventory-list scope used for 2025-2026 quota allocation | H7: 12190431 | I7: 13354978 | J7: Decision 699/QĐ-BNNMT | K7: Official | L7: Do not use this field to infer current post-25/09/2026 inventory-list membership; check the effective list separately.
A8: =OFFICIAL_ALLOCATIONS!A8 -> F007 | B8: Công ty Nhiệt điện Đông Triều - TKV - Nhà máy nhiệt điện Mạo Khê | D8: Electricity | E8: kWh | F8: 0104297034-006 | G8: YES — facility was within the inventory-list scope used for 2025-2026 quota allocation | H8: 4436759 | I8: 4860601 | J8: Decision 699/QĐ-BNNMT | K8: Official | L8: Do not use this field to infer current post-25/09/2026 inventory-list membership; check the effective list separately.
A9: =OFFICIAL_ALLOCATIONS!A9 -> F008 | B9: Nhà máy nhiệt điện Mông Dương I - Công ty Nhiệt điện Mông Dương | D9: Electricity | E9: kWh | F9: 3502208399-008 | G9: YES — facility was within the inventory-list scope used for 2025-2026 quota allocation | H9: 9556403 | I9: 10469322 | J9: Decision 699/QĐ-BNNMT | K9: Official | L9: Do not use this field to infer current post-25/09/2026 inventory-list membership; check the effective list separately.
A10: =OFFICIAL_ALLOCATIONS!A10 -> F009 | B10: Công ty Cổ phần Nhiệt điện Hải Phòng | D10: Electricity | E10: kWh | F10: 200493225 | G10: YES — facility was within the inventory-list scope used for 2025-2026 quota allocation | H10: 10239469 | I10: 11217642 | J10: Decision 699/QĐ-BNNMT | K10: Official | L10: Do not use this field to infer current post-25/09/2026 inventory-list membership; check the effective list separately.
A11: =OFFICIAL_ALLOCATIONS!A11 -> F010 | B11: Nhà máy điện Nghi Sơn 1 | D11: Electricity | E11: kWh | F11: 5701662152-011 | G11: YES — facility was within the inventory-list scope used for 2025-2026 quota allocation | H11: 5036163 | I11: 5517266 | J11: Decision 699/QĐ-BNNMT | K11: Official | L11: Do not use this field to infer current post-25/09/2026 inventory-list membership; check the effective list separately.
A12: =OFFICIAL_ALLOCATIONS!A12 -> F011 | B12: Công ty Điện lực Dầu khí Hà Tĩnh | D12: Electricity | E12: kWh | F12: 0102276173-007 | G12: YES — facility was within the inventory-list scope used for 2025-2026 quota allocation | H12: 7214687 | I12: 7903903 | J12: Decision 699/QĐ-BNNMT | K12: Official | L12: Do not use this field to infer current post-25/09/2026 inventory-list membership; check the effective list separately.
A13: =OFFICIAL_ALLOCATIONS!A13 -> F012 | B13: Công ty TNHH Hưng Nghiệp Formosa | D13: Electricity | E13: kWh | F13: 3600517557 | G13: YES — facility was within the inventory-list scope used for 2025-2026 quota allocation | H13: 2558365 | I13: 2802764 | J13: Decision 699/QĐ-BNNMT | K13: Official | L13: Do not use this field to infer current post-25/09/2026 inventory-list membership; check the effective list separately.
... A111: =OFFICIAL_ALLOCATIONS!A111 -> F110 | B111: Công ty TNHH Duyên Hà, Nhà máy xi măng Duyên Hà | D111: Clinker | E111: t clinker | F111: 0100520789-002 | G111: YES — facility was within the inventory-list scope used for 2025-2026 quota allocation | H111: 1324157 | I111: 1448956 | J111: Decision 699/QĐ-BNNMT | K111: Official | L111: Do not use this field to infer current post-25/09/2026 inventory-list membership; check the effective list separately.

Sheet CALCULATION
A1: Facility ID | B1: Facility Name | C1: Sector | D1: Allocation Year | E1: Window Start | F1: Window End | G1: P_avg | H1: E_avg | I1: Sector Data Completeness | J1: Sector Benchmark (B) | K1: g | L1: r | M1: T | N1: Calculated Allocation (A) | O1: Official Allocation | P1: Difference | Q1: Difference % | R1: Calculation Status | S1: Legal Basis | T1: Source URL
A2: F001 | B2: Công ty nhiệt điện Na Dương | C2: Thermal power | D2: 2025 | E2: =D2-3 -> 2022 | F2: =D2-1 -> 2024 | G2: =IF(COUNTIFS(HISTORICAL_DATA!$A$2:$A$441,$A2,HISTORICAL_DATA!$D$2:$D$441,">="&$E2,HISTORICAL_DATA!$D$2:$D$441,"<="&$F2,HISTORICAL_DATA!$E$2:$E$441,"<>")<3,"",SUMIFS(HISTORICAL_DATA!$E$2:$E$441,HISTORICAL_DATA!$A$2:$A$441,$A2,HISTORICAL_DATA!$D$2:$D$441,">="&$E2,HISTORICAL_DATA!$D$2:$D$441,"<="&$F2)/3) | H2: =IF(COUNTIFS(HISTORICAL_DATA!$A$2:$A$441,$A2,HISTORICAL_DATA!$D$2:$D$441,">="&$E2,HISTORICAL_DATA!$D$2:$D$441,"<="&$F2,HISTORICAL_DATA!$E$2:$E$441,"<>")<3,"",SUMIFS(HISTORICAL_DATA!$E$2:$E$441,HISTORICAL_DATA!$A$2:$A$441,$A2,HISTORICAL_DATA!$D$2:$D$441,">="&$E2,HISTORICAL_DATA!$D$2:$D$441,"<="&$F2)/3) | I2: =IF(OR(G2="",H2=""),"FACILITY DATA MISSING",IF(AND(COUNTIFS($C$2:$C$221,C2,$D$2:$D$221,D2,$G$2:$G$221,"<>")=COUNTIF(OFFICIAL_ALLOCATIONS!$C$2:$C$111,C2),COUNTIFS($C$2:$C$221,C2,$D$2:$D$221,D2,$H$2:$H$221,"<>")=COUNTIF(OFFICIAL_ALLOCATIONS!$C$2:$C$111,C2)),"COMPLETE","SECTOR DATA INCOMPLETE")) -> FACILITY DATA MISSING | J2: =IF(I2<>"COMPLETE","",IFERROR(SUMIFS($H$2:$H$221,$C$2:$C$221,C2,$D$2:$D$221,D2)/SUMIFS($G$2:$G$221,$C$2:$C$221,C2,$D$2:$D$221,D2),"")) | K2: =IF(COUNTIFS(POLICY_PARAMETERS!$B$2:$B$13,"g",POLICY_PARAMETERS!$E$2:$E$13,C2,POLICY_PARAMETERS!$F$2:$F$13,D2,POLICY_PARAMETERS!$G$2:$G$13,"<>")=0,"",SUMIFS(POLICY_PARAMETERS!$G$2:$G$13,POLICY_PARAMETERS!$B$2:$B$13,"g",POLICY_PARAMETERS!$E$2:$E$13,C2,POLICY_PARAMETERS!$F$2:$F$13,D2)) | L2: =IF(COUNTIFS(POLICY_PARAMETERS!$B$2:$B$13,"r",POLICY_PARAMETERS!$E$2:$E$13,C2,POLICY_PARAMETERS!$F$2:$F$13,D2,POLICY_PARAMETERS!$G$2:$G$13,"<>")=0,"",SUMIFS(POLICY_PARAMETERS!$G$2:$G$13,POLICY_PARAMETERS!$B$2:$B$13,"r",POLICY_PARAMETERS!$E$2:$E$13,C2,POLICY_PARAMETERS!$F$2:$F$13,D2)) | M2: =IF(OR(K2="",L2=""),"",(1+K2)*(1-L2)) | N2: =IF(OR(G2="",J2="",M2=""),"",G2*J2*M2) | O2: =IF(D2=2025,IFERROR(VLOOKUP(A2,OFFICIAL_ALLOCATIONS!$A$2:$F$111,5,FALSE),""),IFERROR(VLOOKUP(A2,OFFICIAL_ALLOCATIONS!$A$2:$F$111,6,FALSE),"")) -> 1035566 | P2: =IF(OR(N2="",O2=""),"",N2-O2) | Q2: =IF(OR(P2="",O2=0),"",P2/O2) | R2: =IF(OR(G2="",H2=""),"MISSING HISTORICAL DATA",IF(I2<>"COMPLETE","INCOMPLETE SECTOR DATA",IF(OR(K2="",L2=""),"MISSING VERIFIED g/r",IF(N2="","NOT READY","READY")))) -> MISSING HISTORICAL DATA | S2: Appendix I, Method No. 01 | T2: https://datafiles.chinhphu.vn/cpp/files/vbpq/2025/6/10-vbhn-bnnmt-kem.pdf
A3: F001 | B3: Công ty nhiệt điện Na Dương | C3: Thermal power | D3: 2026 | E3: =D3-3 -> 2023 | F3: =D3-1 -> 2025 | G3: =IF(COUNTIFS(HISTORICAL_DATA!$A$2:$A$441,$A3,HISTORICAL_DATA!$D$2:$D$441,">="&$E3,HISTORICAL_DATA!$D$2:$D$441,"<="&$F3,HISTORICAL_DATA!$E$2:$E$441,"<>")<3,"",SUMIFS(HISTORICAL_DATA!$E$2:$E$441,HISTORICAL_DATA!$A$2:$A$441,$A3,HISTORICAL_DATA!$D$2:$D$441,">="&$E3,HISTORICAL_DATA!$D$2:$D$441,"<="&$F3)/3) | H3: =IF(COUNTIFS(HISTORICAL_DATA!$A$2:$A$441,$A3,HISTORICAL_DATA!$D$2:$D$441,">="&$E3,HISTORICAL_DATA!$D$2:$D$441,"<="&$F3,HISTORICAL_DATA!$G$2:$G$441,"<>")<3,"",SUMIFS(HISTORICAL_DATA!$G$2:$G$441,HISTORICAL_DATA!$A$2:$A$441,$A3,HISTORICAL_DATA!$D$2:$D$441,">="&$E3,HISTORICAL_DATA!$D$2:$D$441,"<="&$F3)/3) | I3: =IF(OR(G3="",H3=""),"FACILITY DATA MISSING",IF(AND(COUNTIFS($C$2:$C$221,C3,$D$2:$D$221,D3,$G$2:$G$221,"<>")=COUNTIF(OFFICIAL_ALLOCATIONS!$C$2:$C$111,C3),COUNTIFS($C$2:$C$221,C3,$D$2:$D$221,D3,$H$2:$H$221,"<>")=COUNTIF(OFFICIAL_ALLOCATIONS!$C$2:$C$111,C3)),"COMPLETE","SECTOR DATA INCOMPLETE")) -> FACILITY DATA MISSING | J3: =IF(I3<>"COMPLETE","",IFERROR(SUMIFS($H$2:$H$221,$C$2:$C$221,C3,$D$2:$D$221,D3)/SUMIFS($G$2:$G$221,$C$2:$C$221,C3,$D$2:$D$221,D3),"")) | K3: =IF(COUNTIFS(POLICY_PARAMETERS!$B$2:$B$13,"g",POLICY_PARAMETERS!$E$2:$E$13,C3,POLICY_PARAMETERS!$F$2:$F$13,D3,POLICY_PARAMETERS!$G$2:$G$13,"<>")=0,"",SUMIFS(POLICY_PARAMETERS!$G$2:$G$13,POLICY_PARAMETERS!$B$2:$B$13,"g",POLICY_PARAMETERS!$E$2:$E$13,C3,POLICY_PARAMETERS!$F$2:$F$13,D3)) | L3: =IF(COUNTIFS(POLICY_PARAMETERS!$B$2:$B$13,"r",POLICY_PARAMETERS!$E$2:$E$13,C3,POLICY_PARAMETERS!$F$2:$F$13,D3,POLICY_PARAMETERS!$G$2:$G$13,"<>")=0,"",SUMIFS(POLICY_PARAMETERS!$G$2:$G$13,POLICY_PARAMETERS!$B$2:$B$13,"r",POLICY_PARAMETERS!$E$2:$E$13,C3,POLICY_PARAMETERS!$F$2:$F$13,D3)) | M3: =IF(OR(K3="",L3=""),"",(1+K3)*(1-L3)) | N3: =IF(OR(G3="",J3="",M3=""),"",G3*J3*M3) | O3: =IF(D3=2025,IFERROR(VLOOKUP(A3,OFFICIAL_ALLOCATIONS!$A$2:$F$111,5,FALSE),""),IFERROR(VLOOKUP(A3,OFFICIAL_ALLOCATIONS!$A$2:$F$111,6,FALSE),"")) -> 1134493 | P3: =IF(OR(N3="",O3=""),"",N3-O3) | Q3: =IF(OR(P3="",O3=0),"",P3/O3) | R3: =IF(OR(G3="",H3=""),"MISSING HISTORICAL DATA",IF(I3<>"COMPLETE","INCOMPLETE SECTOR DATA",IF(OR(K3="",L3=""),"MISSING VERIFIED g/r",IF(N3="","NOT READY","READY")))) -> MISSING HISTORICAL DATA | S3: Appendix I, Method No. 01 | T3: https://datafiles.chinhphu.vn/cpp/files/vbpq/2025/6/10-vbhn-bnnmt-kem.pdf
A4: F002 | B4: Công ty nhiệt điện Sơn động Việt Nam | C4: Thermal power | D4: 2025 | E4: =D4-3 -> 2022 | F4: =D4-1 -> 2024 | G4: =IF(COUNTIFS(HISTORICAL_DATA!$A$2:$A$441,$A4,HISTORICAL_DATA!$D$2:$D$441,">="&$E4,HISTORICAL_DATA!$D$2:$D$441,"<="&$F4,HISTORICAL_DATA!$E$2:$E$441,"<>")<3,"",SUMIFS(HISTORICAL_DATA!$E$2:$E$441,HISTORICAL_DATA!$A$2:$A$441,$A4,HISTORICAL_DATA!$D$2:$D$441,">="&$E4,HISTORICAL_DATA!$D$2:$D$441,"<="&$F4)/3) | H4: =IF(COUNTIFS(HISTORICAL_DATA!$A$2:$A$441,$A4,HISTORICAL_DATA!$D$2:$D$441,">="&$E4,HISTORICAL_DATA!$D$2:$D$441,"<="&$F4,HISTORICAL_DATA!$G$2:$G$441,"<>")<3,"",SUMIFS(HISTORICAL_DATA!$G$2:$G$441,HISTORICAL_DATA!$A$2:$A$441,$A4,HISTORICAL_DATA!$D$2:$D$441,">="&$E4,HISTORICAL_DATA!$D$2:$D$441,"<="&$F4)/3) | I4: =IF(OR(G4="",H4=""),"FACILITY DATA MISSING",IF(AND(COUNTIFS($C$2:$C$221,C4,$D$2:$D$221,D4,$G$2:$G$221,"<>")=COUNTIF(OFFICIAL_ALLOCATIONS!$C$2:$C$111,C4),COUNTIFS($C$2:$C$221,C4,$D$2:$D$221,D4,$H$2:$H$221,"<>")=COUNTIF(OFFICIAL_ALLOCATIONS!$C$2:$C$111,C4)),"COMPLETE","SECTOR DATA INCOMPLETE")) -> FACILITY DATA MISSING | J4: =IF(I4<>"COMPLETE","",IFERROR(SUMIFS($H$2:$H$221,$C$2:$C$221,C4,$D$2:$D$221,D4)/SUMIFS($G$2:$G$221,$C$2:$C$221,C4,$D$2:$D$221,D4),"")) | K4: =IF(COUNTIFS(POLICY_PARAMETERS!$B$2:$B$13,"g",POLICY_PARAMETERS!$E$2:$E$13,C4,POLICY_PARAMETERS!$F$2:$F$13,D4,POLICY_PARAMETERS!$G$2:$G$13,"<>")=0,"",SUMIFS(POLICY_PARAMETERS!$G$2:$G$13,POLICY_PARAMETERS!$B$2:$B$13,"g",POLICY_PARAMETERS!$E$2:$E$13,C4,POLICY_PARAMETERS!$F$2:$F$13,D4)) | L4: =IF(COUNTIFS(POLICY_PARAMETERS!$B$2:$B$13,"r",POLICY_PARAMETERS!$E$2:$E$13,C4,POLICY_PARAMETERS!$F$2:$F$13,D4,POLICY_PARAMETERS!$G$2:$G$13,"<>")=0,"",SUMIFS(POLICY_PARAMETERS!$G$2:$G$13,POLICY_PARAMETERS!$B$2:$B$13,"r",POLICY_PARAMETERS!$E$2:$E$13,C4,POLICY_PARAMETERS!$F$2:$F$13,D4)) | M4: =IF(OR(K4="",L4=""),"",(1+K4)*(1-L4)) | N4: =IF(OR(G4="",J4="",M4=""),"",G4*J4*M4) | O4: =IF(D4=2025,IFERROR(VLOOKUP(A4,OFFICIAL_ALLOCATIONS!$A$2:$F$111,5,FALSE),""),IFERROR(VLOOKUP(A4,OFFICIAL_ALLOCATIONS!$A$2:$F$111,6,FALSE),"")) -> 2032458 | P4: =IF(OR(N4="",O4=""),"",N4-O4) | Q4: =IF(OR(P4="",O4=0),"",P4/O4) | R4: =IF(OR(G4="",H4=""),"MISSING HISTORICAL DATA",IF(I4<>"COMPLETE","INCOMPLETE SECTOR DATA",IF(OR(K4="",L4=""),"MISSING VERIFIED g/r",IF(N4="","NOT READY","READY")))) -> MISSING HISTORICAL DATA | S4: Appendix I, Method No. 01 | T4: https://datafiles.chinhphu.vn/cpp/files/vbpq/2025/6/10-vbhn-bnnmt-kem.pdf
A5: F002 | B5: Công ty nhiệt điện Sơn động Việt Nam | C5: Thermal power | D5: 2026 | E5: =D5-3 -> 2023 | F5: =D5-1 -> 2025 | G5: =IF(COUNTIFS(HISTORICAL_DATA!$A$2:$A$441,$A5,HISTORICAL_DATA!$D$2:$D$441,">="&$E5,HISTORICAL_DATA!$D$2:$D$441,"<="&$F5,HISTORICAL_DATA!$E$2:$E$441,"<>")<3,"",SUMIFS(HISTORICAL_DATA!$E$2:$E$441,HISTORICAL_DATA!$A$2:$A$441,$A5,HISTORICAL_DATA!$D$2:$D$441,">="&$E5,HISTORICAL_DATA!$D$2:$D$441,"<="&$F5)/3) | H5: =IF(COUNTIFS(HISTORICAL_DATA!$A$2:$A$441,$A5,HISTORICAL_DATA!$D$2:$D$441,">="&$E5,HISTORICAL_DATA!$D$2:$D$441,"<="&$F5,HISTORICAL_DATA!$G$2:$G$441,"<>")<3,"",SUMIFS(HISTORICAL_DATA!$G$2:$G$441,HISTORICAL_DATA!$A$2:$A$441,$A5,HISTORICAL_DATA!$D$2:$D$441,">="&$E5,HISTORICAL_DATA!$D$2:$D$441,"<="&$F5)/3) | I5: =IF(OR(G5="",H5=""),"FACILITY DATA MISSING",IF(AND(COUNTIFS($C$2:$C$221,C5,$D$2:$D$221,D5,$G$2:$G$221,"<>")=COUNTIF(OFFICIAL_ALLOCATIONS!$C$2:$C$111,C5),COUNTIFS($C$2:$C$221,C5,$D$2:$D$221,D5,$H$2:$H$221,"<>")=COUNTIF(OFFICIAL_ALLOCATIONS!$C$2:$C$111,C5)),"COMPLETE","SECTOR DATA INCOMPLETE")) -> FACILITY DATA MISSING | J5: =IF(I5<>"COMPLETE","",IFERROR(SUMIFS($H$2:$H$221,$C$2:$C$221,C5,$D$2:$D$221,D5)/SUMIFS($G$2:$G$221,$C$2:$C$221,C5,$D$2:$D$221,D5),"")) | K5: =IF(COUNTIFS(POLICY_PARAMETERS!$B$2:$B$13,"g",POLICY_PARAMETERS!$E$2:$E$13,C5,POLICY_PARAMETERS!$F$2:$F$13,D5,POLICY_PARAMETERS!$G$2:$G$13,"<>")=0,"",SUMIFS(POLICY_PARAMETERS!$G$2:$G$13,POLICY_PARAMETERS!$B$2:$B$13,"g",POLICY_PARAMETERS!$E$2:$E$13,C5,POLICY_PARAMETERS!$F$2:$F$13,D5)) | L5: =IF(COUNTIFS(POLICY_PARAMETERS!$B$2:$B$13,"r",POLICY_PARAMETERS!$E$2:$E$13,C5,POLICY_PARAMETERS!$F$2:$F$13,D5,POLICY_PARAMETERS!$G$2:$G$13,"<>")=0,"",SUMIFS(POLICY_PARAMETERS!$G$2:$G$13,POLICY_PARAMETERS!$B$2:$B$13,"r",POLICY_PARAMETERS!$E$2:$E$13,C5,POLICY_PARAMETERS!$F$2:$F$13,D5)) | M5: =IF(OR(K5="",L5=""),"",(1+K5)*(1-L5)) | N5: =IF(OR(G5="",J5="",M5=""),"",G5*J5*M5) | O5: =IF(D5=2025,IFERROR(VLOOKUP(A5,OFFICIAL_ALLOCATIONS!$A$2:$F$111,5,FALSE),""),IFERROR(VLOOKUP(A5,OFFICIAL_ALLOCATIONS!$A$2:$F$111,6,FALSE),"")) -> 2226618 | P5: =IF(OR(N5="",O5=""),"",N5-O5) | Q5: =IF(OR(P5="",O5=0),"",P5/O5) | R5: =IF(OR(G5="",H5=""),"MISSING HISTORICAL DATA",IF(I5<>"COMPLETE","INCOMPLETE SECTOR DATA",IF(OR(K5="",L5=""),"MISSING VERIFIED g/r",IF(N5="","NOT READY","READY")))) -> MISSING HISTORICAL DATA | S5: Appendix I, Method No. 01 | T5: https://datafiles.chinhphu.vn/cpp/files/vbpq/2025/6/10-vbhn-bnnmt-kem.pdf
A6: F003 | B6: Công ty Nhiệt điện Uông Bí | C6: Thermal power | D6: 2025 | E6: =D6-3 -> 2022 | F6: =D6-1 -> 2024 | G6: =IF(COUNTIFS(HISTORICAL_DATA!$A$2:$A$441,$A6,HISTORICAL_DATA!$D$2:$D$441,">="&$E6,HISTORICAL_DATA!$D$2:$D$441,"<="&$F6,HISTORICAL_DATA!$E$2:$E$441,"<>")<3,"",SUMIFS(HISTORICAL_DATA!$E$2:$E$441,HISTORICAL_DATA!$A$2:$A$441,$A6,HISTORICAL_DATA!$D$2:$D$441,">="&$E6,HISTORICAL_DATA!$D$2:$D$441,"<="&$F6)/3) | H6: =IF(COUNTIFS(HISTORICAL_DATA!$A$2:$A$441,$A6,HISTORICAL_DATA!$D$2:$D$441,">="&$E6,HISTORICAL_DATA!$D$2:$D$441,"<="&$F6,HISTORICAL_DATA!$G$2:$G$441,"<>")<3,"",SUMIFS(HISTORICAL_DATA!$G$2:$G$441,HISTORICAL_DATA!$A$2:$A$441,$A6,HISTORICAL_DATA!$D$2:$D$441,">="&$E6,HISTORICAL_DATA!$D$2:$D$441,"<="&$F6)/3) | I6: =IF(OR(G6="",H6=""),"FACILITY DATA MISSING",IF(AND(COUNTIFS($C$2:$C$221,C6,$D$2:$D$221,D6,$G$2:$G$221,"<>")=COUNTIF(OFFICIAL_ALLOCATIONS!$C$2:$C$111,C6),COUNTIFS($C$2:$C$221,C6,$D$2:$D$221,D6,$H$2:$H$221,"<>")=COUNTIF(OFFICIAL_ALLOCATIONS!$C$2:$C$111,C6)),"COMPLETE","SECTOR DATA INCOMPLETE")) -> FACILITY DATA MISSING | J6: =IF(I6<>"COMPLETE","",IFERROR(SUMIFS($H$2:$H$221,$C$2:$C$221,C6,$D$2:$D$221,D6)/SUMIFS($G$2:$G$221,$C$2:$C$221,C6,$D$2:$D$221,D6),"")) | K6: =IF(COUNTIFS(POLICY_PARAMETERS!$B$2:$B$13,"g",POLICY_PARAMETERS!$E$2:$E$13,C6,POLICY_PARAMETERS!$F$2:$F$13,D6,POLICY_PARAMETERS!$G$2:$G$13,"<>")=0,"",SUMIFS(POLICY_PARAMETERS!$G$2:$G$13,POLICY_PARAMETERS!$B$2:$B$13,"g",POLICY_PARAMETERS!$E$2:$E$13,C6,POLICY_PARAMETERS!$F$2:$F$13,D6)) | L6: =IF(COUNTIFS(POLICY_PARAMETERS!$B$2:$B$13,"r",POLICY_PARAMETERS!$E$2:$E$13,C6,POLICY_PARAMETERS!$F$2:$F$13,D6,POLICY_PARAMETERS!$G$2:$G$13,"<>")=0,"",SUMIFS(POLICY_PARAMETERS!$G$2:$G$13,POLICY_PARAMETERS!$B$2:$B$13,"r",POLICY_PARAMETERS!$E$2:$E$13,C6,POLICY_PARAMETERS!$F$2:$F$13,D6)) | M6: =IF(OR(K6="",L6=""),"",(1+K6)*(1-L6)) | N6: =IF(OR(G6="",J6="",M6=""),"",G6*J6*M6) | O6: =IF(D6=2025,IFERROR(VLOOKUP(A6,OFFICIAL_ALLOCATIONS!$A$2:$F$111,5,FALSE),""),IFERROR(VLOOKUP(A6,OFFICIAL_ALLOCATIONS!$A$2:$F$111,6,FALSE),"")) -> 5691098 | P6: =IF(OR(N6="",O6=""),"",N6-O6) | Q6: =IF(OR(P6="",O6=0),"",P6/O6) | R6: =IF(OR(G6="",H6=""),"MISSING HISTORICAL DATA",IF(I6<>"COMPLETE","INCOMPLETE SECTOR DATA",IF(OR(K6="",L6=""),"MISSING VERIFIED g/r",IF(N6="","NOT READY","READY")))) -> MISSING HISTORICAL DATA | S6: Appendix I, Method No. 01 | T6: https://datafiles.chinhphu.vn/cpp/files/vbpq/2025/6/10-vbhn-bnnmt-kem.pdf
A7: F003 | B7: Công ty Nhiệt điện Uông Bí | C7: Thermal power | D7: 2026 | E7: =D7-3 -> 2023 | F7: =D7-1 -> 2025 | G7: =IF(COUNTIFS(HISTORICAL_DATA!$A$2:$A$441,$A7,HISTORICAL_DATA!$D$2:$D$441,">="&$E7,HISTORICAL_DATA!$D$2:$D$441,"<="&$F7,HISTORICAL_DATA!$E$2:$E$441,"<>")<3,"",SUMIFS(HISTORICAL_DATA!$E$2:$E$441,HISTORICAL_DATA!$A$2:$A$441,$A7,HISTORICAL_DATA!$D$2:$D$441,">="&$E7,HISTORICAL_DATA!$D$2:$D$441,"<="&$F7)/3) | H7: =IF(COUNTIFS(HISTORICAL_DATA!$A$2:$A$441,$A7,HISTORICAL_DATA!$D$2:$D$441,">="&$E7,HISTORICAL_DATA!$D$2:$D$441,"<="&$F7,HISTORICAL_DATA!$G$2:$G$441,"<>")<3,"",SUMIFS(HISTORICAL_DATA!$G$2:$G$441,HISTORICAL_DATA!$A$2:$A$441,$A7,HISTORICAL_DATA!$D$2:$D$441,">="&$E7,HISTORICAL_DATA!$D$2:$D$441,"<="&$F7)/3) | I7: =IF(OR(G7="",H7=""),"FACILITY DATA MISSING",IF(AND(COUNTIFS($C$2:$C$221,C7,$D$2:$D$221,D7,$G$2:$G$221,"<>")=COUNTIF(OFFICIAL_ALLOCATIONS!$C$2:$C$111,C7),COUNTIFS($C$2:$C$221,C7,$D$2:$D$221,D7,$H$2:$H$221,"<>")=COUNTIF(OFFICIAL_ALLOCATIONS!$C$2:$C$111,C7)),"COMPLETE","SECTOR DATA INCOMPLETE")) -> FACILITY DATA MISSING | J7: =IF(I7<>"COMPLETE","",IFERROR(SUMIFS($H$2:$H$221,$C$2:$C$221,C7,$D$2:$D$221,D7)/SUMIFS($G$2:$G$221,$C$2:$C$221,C7,$D$2:$D$221,D7),"")) | K7: =IF(COUNTIFS(POLICY_PARAMETERS!$B$2:$B$13,"g",POLICY_PARAMETERS!$E$2:$E$13,C7,POLICY_PARAMETERS!$F$2:$F$13,D7,POLICY_PARAMETERS!$G$2:$G$13,"<>")=0,"",SUMIFS(POLICY_PARAMETERS!$G$2:$G$13,POLICY_PARAMETERS!$B$2:$B$13,"g",POLICY_PARAMETERS!$E$2:$E$13,C7,POLICY_PARAMETERS!$F$2:$F$13,D7)) | L7: =IF(COUNTIFS(POLICY_PARAMETERS!$B$2:$B$13,"r",POLICY_PARAMETERS!$E$2:$E$13,C7,POLICY_PARAMETERS!$F$2:$F$13,D7,POLICY_PARAMETERS!$G$2:$G$13,"<>")=0,"",SUMIFS(POLICY_PARAMETERS!$G$2:$G$13,POLICY_PARAMETERS!$B$2:$B$13,"r",POLICY_PARAMETERS!$E$2:$E$13,C7,POLICY_PARAMETERS!$F$2:$F$13,D7)) | M7: =IF(OR(K7="",L7=""),"",(1+K7)*(1-L7)) | N7: =IF(OR(G7="",J7="",M7=""),"",G7*J7*M7) | O7: =IF(D7=2025,IFERROR(VLOOKUP(A7,OFFICIAL_ALLOCATIONS!$A$2:$F$111,5,FALSE),""),IFERROR(VLOOKUP(A7,OFFICIAL_ALLOCATIONS!$A$2:$F$111,6,FALSE),"")) -> 6234766 | P7: =IF(OR(N7="",O7=""),"",N7-O7) | Q7: =IF(OR(P7="",O7=0),"",P7/O7) | R7: =IF(OR(G7="",H7=""),"MISSING HISTORICAL DATA",IF(I7<>"COMPLETE","INCOMPLETE SECTOR DATA",IF(OR(K7="",L7=""),"MISSING VERIFIED g/r",IF(N7="","NOT READY","READY")))) -> MISSING HISTORICAL DATA | S7: Appendix I, Method No. 01 | T7: https://datafiles.chinhphu.vn/cpp/files/vbpq/2025/6/10-vbhn-bnnmt-kem.pdf
A8: F004 | B8: Công ty Cổ phần Nhiệt điện Quảng Ninh | C8: Thermal power | D8: 2025 | E8: =D8-3 -> 2022 | F8: =D8-1 -> 2024 | G8: =IF(COUNTIFS(HISTORICAL_DATA!$A$2:$A$441,$A8,HISTORICAL_DATA!$D$2:$D$441,">="&$E8,HISTORICAL_DATA!$D$2:$D$441,"<="&$F8,HISTORICAL_DATA!$E$2:$E$441,"<>")<3,"",SUMIFS(HISTORICAL_DATA!$E$2:$E$441,HISTORICAL_DATA!$A$2:$A$441,$A8,HISTORICAL_DATA!$D$2:$D$441,">="&$E8,HISTORICAL_DATA!$D$2:$D$441,"<="&$F8)/3) | H8: =IF(COUNTIFS(HISTORICAL_DATA!$A$2:$A$441,$A8,HISTORICAL_DATA!$D$2:$D$441,">="&$E8,HISTORICAL_DATA!$D$2:$D$441,"<="&$F8,HISTORICAL_DATA!$G$2:$G$441,"<>")<3,"",SUMIFS(HISTORICAL_DATA!$G$2:$G$441,HISTORICAL_DATA!$A$2:$A$441,$A8,HISTORICAL_DATA!$D$2:$D$441,">="&$E8,HISTORICAL_DATA!$D$2:$D$441,"<="&$F8)/3) | I8: =IF(OR(G8="",H8=""),"FACILITY DATA MISSING",IF(AND(COUNTIFS($C$2:$C$221,C8,$D$2:$D$221,D8,$G$2:$G$221,"<>")=COUNTIF(OFFICIAL_ALLOCATIONS!$C$2:$C$111,C8),COUNTIFS($C$2:$C$221,C8,$D$2:$D$221,D8,$H$2:$H$221,"<>")=COUNTIF(OFFICIAL_ALLOCATIONS!$C$2:$C$111,C8)),"COMPLETE","SECTOR DATA INCOMPLETE")) -> FACILITY DATA MISSING | J8: =IF(I8<>"COMPLETE","",IFERROR(SUMIFS($H$2:$H$221,$C$2:$C$221,C8,$D$2:$D$221,D8)/SUMIFS($G$2:$G$221,$C$2:$C$221,C8,$D$2:$D$221,D8),"")) | K8: =IF(COUNTIFS(POLICY_PARAMETERS!$B$2:$B$13,"g",POLICY_PARAMETERS!$E$2:$E$13,C8,POLICY_PARAMETERS!$F$2:$F$13,D8,POLICY_PARAMETERS!$G$2:$G$13,"<>")=0,"",SUMIFS(POLICY_PARAMETERS!$G$2:$G$13,POLICY_PARAMETERS!$B$2:$B$13,"g",POLICY_PARAMETERS!$E$2:$E$13,C8,POLICY_PARAMETERS!$F$2:$F$13,D8)) | L8: =IF(COUNTIFS(POLICY_PARAMETERS!$B$2:$B$13,"r",POLICY_PARAMETERS!$E$2:$E$13,C8,POLICY_PARAMETERS!$F$2:$F$13,D8,POLICY_PARAMETERS!$G$2:$G$13,"<>")=0,"",SUMIFS(POLICY_PARAMETERS!$G$2:$G$13,POLICY_PARAMETERS!$B$2:$B$13,"r",POLICY_PARAMETERS!$E$2:$E$13,C8,POLICY_PARAMETERS!$F$2:$F$13,D8)) | M8: =IF(OR(K8="",L8=""),"",(1+K8)*(1-L8)) | N8: =IF(OR(G8="",J8="",M8=""),"",G8*J8*M8) | O8: =IF(D8=2025,IFERROR(VLOOKUP(A8,OFFICIAL_ALLOCATIONS!$A$2:$F$111,5,FALSE),""),IFERROR(VLOOKUP(A8,OFFICIAL_ALLOCATIONS!$A$2:$F$111,6,FALSE),"")) -> 11097421 | P8: =IF(OR(N8="",O8=""),"",N8-O8) | Q8: =IF(OR(P8="",O8=0),"",P8/O8) | R8: =IF(OR(G8="",H8=""),"MISSING HISTORICAL DATA",IF(I8<>"COMPLETE","INCOMPLETE SECTOR DATA",IF(OR(K8="",L8=""),"MISSING VERIFIED g/r",IF(N8="","NOT READY","READY")))) -> MISSING HISTORICAL DATA | S8: Appendix I, Method No. 01 | T8: https://datafiles.chinhphu.vn/cpp/files/vbpq/2025/6/10-vbhn-bnnmt-kem.pdf
A9: F004 | B9: Công ty Cổ phần Nhiệt điện Quảng Ninh | C9: Thermal power | D9: 2026 | E9: =D9-3 -> 2023 | F9: =D9-1 -> 2025 | G9: =IF(COUNTIFS(HISTORICAL_DATA!$A$2:$A$441,$A9,HISTORICAL_DATA!$D$2:$D$441,">="&$E9,HISTORICAL_DATA!$D$2:$D$441,"<="&$F9,HISTORICAL_DATA!$E$2:$E$441,"<>")<3,"",SUMIFS(HISTORICAL_DATA!$E$2:$E$441,HISTORICAL_DATA!$A$2:$A$441,$A9,HISTORICAL_DATA!$D$2:$D$441,">="&$E9,HISTORICAL_DATA!$D$2:$D$441,"<="&$F9)/3) | H9: =IF(COUNTIFS(HISTORICAL_DATA!$A$2:$A$441,$A9,HISTORICAL_DATA!$D$2:$D$441,">="&$E9,HISTORICAL_DATA!$D$2:$D$441,"<="&$F9,HISTORICAL_DATA!$G$2:$G$441,"<>")<3,"",SUMIFS(HISTORICAL_DATA!$G$2:$G$441,HISTORICAL_DATA!$A$2:$A$441,$A9,HISTORICAL_DATA!$D$2:$D$441,">="&$E9,HISTORICAL_DATA!$D$2:$D$441,"<="&$F9)/3) | I9: =IF(OR(G9="",H9=""),"FACILITY DATA MISSING",IF(AND(COUNTIFS($C$2:$C$221,C9,$D$2:$D$221,D9,$G$2:$G$221,"<>")=COUNTIF(OFFICIAL_ALLOCATIONS!$C$2:$C$111,C9),COUNTIFS($C$2:$C$221,C9,$D$2:$D$221,D9,$H$2:$H$221,"<>")=COUNTIF(OFFICIAL_ALLOCATIONS!$C$2:$C$111,C9)),"COMPLETE","SECTOR DATA INCOMPLETE")) -> FACILITY DATA MISSING | J9: =IF(I9<>"COMPLETE","",IFERROR(SUMIFS($H$2:$H$221,$C$2:$C$221,C9,$D$2:$D$221,D9)/SUMIFS($G$2:$G$221,$C$2:$C$221,C9,$D$2:$D$221,D9),"")) | K9: =IF(COUNTIFS(POLICY_PARAMETERS!$B$2:$B$13,"g",POLICY_PARAMETERS!$E$2:$E$13,C9,POLICY_PARAMETERS!$F$2:$F$13,D9,POLICY_PARAMETERS!$G$2:$G$13,"<>")=0,"",SUMIFS(POLICY_PARAMETERS!$G$2:$G$13,POLICY_PARAMETERS!$B$2:$B$13,"g",POLICY_PARAMETERS!$E$2:$E$13,C9,POLICY_PARAMETERS!$F$2:$F$13,D9)) | L9: =IF(COUNTIFS(POLICY_PARAMETERS!$B$2:$B$13,"r",POLICY_PARAMETERS!$E$2:$E$13,C9,POLICY_PARAMETERS!$F$2:$F$13,D9,POLICY_PARAMETERS!$G$2:$G$13,"<>")=0,"",SUMIFS(POLICY_PARAMETERS!$G$2:$G$13,POLICY_PARAMETERS!$B$2:$B$13,"r",POLICY_PARAMETERS!$E$2:$E$13,C9,POLICY_PARAMETERS!$F$2:$F$13,D9)) | M9: =IF(OR(K9="",L9=""),"",(1+K9)*(1-L9)) | N9: =IF(OR(G9="",J9="",M9=""),"",G9*J9*M9) | O9: =IF(D9=2025,IFERROR(VLOOKUP(A9,OFFICIAL_ALLOCATIONS!$A$2:$F$111,5,FALSE),""),IFERROR(VLOOKUP(A9,OFFICIAL_ALLOCATIONS!$A$2:$F$111,6,FALSE),"")) -> 12157553 | P9: =IF(OR(N9="",O9=""),"",N9-O9) | Q9: =IF(OR(P9="",O9=0),"",P9/O9) | R9: =IF(OR(G9="",H9=""),"MISSING HISTORICAL DATA",IF(I9<>"COMPLETE","INCOMPLETE SECTOR DATA",IF(OR(K9="",L9=""),"MISSING VERIFIED g/r",IF(N9="","NOT READY","READY")))) -> MISSING HISTORICAL DATA | S9: Appendix I, Method No. 01 | T9: https://datafiles.chinhphu.vn/cpp/files/vbpq/2025/6/10-vbhn-bnnmt-kem.pdf
A10: F005 | B10: Công ty Nhiệt điện Cẩm Phả - TKV | C10: Thermal power | D10: 2025 | E10: =D10-3 -> 2022 | F10: =D10-1 -> 2024 | G10: =IF(COUNTIFS(HISTORICAL_DATA!$A$2:$A$441,$A10,HISTORICAL_DATA!$D$2:$D$441,">="&$E10,HISTORICAL_DATA!$D$2:$D$441,"<="&$F10,HISTORICAL_DATA!$E$2:$E$441,"<>")<3,"",SUMIFS(HISTORICAL_DATA!$E$2:$E$441,HISTORICAL_DATA!$A$2:$A$441,$A10,HISTORICAL_DATA!$D$2:$D$441,">="&$E10,HISTORICAL_DATA!$D$2:$D$441,"<="&$F10)/3) | H10: =IF(COUNTIFS(HISTORICAL_DATA!$A$2:$A$441,$A10,HISTORICAL_DATA!$D$2:$D$441,">="&$E10,HISTORICAL_DATA!$D$2:$D$441,"<="&$F10,HISTORICAL_DATA!$G$2:$G$441,"<>")<3,"",SUMIFS(HISTORICAL_DATA!$G$2:$G$441,HISTORICAL_DATA!$A$2:$A$441,$A10,HISTORICAL_DATA!$D$2:$D$441,">="&$E10,HISTORICAL_DATA!$D$2:$D$441,"<="&$F10)/3) | I10: =IF(OR(G10="",H10=""),"FACILITY DATA MISSING",IF(AND(COUNTIFS($C$2:$C$221,C10,$D$2:$D$221,D10,$G$2:$G$221,"<>")=COUNTIF(OFFICIAL_ALLOCATIONS!$C$2:$C$111,C10),COUNTIFS($C$2:$C$221,C10,$D$2:$D$221,D10,$H$2:$H$221,"<>")=COUNTIF(OFFICIAL_ALLOCATIONS!$C$2:$C$111,C10)),"COMPLETE","SECTOR DATA INCOMPLETE")) -> FACILITY DATA MISSING | J10: =IF(I10<>"COMPLETE","",IFERROR(SUMIFS($H$2:$H$221,$C$2:$C$221,C10,$D$2:$D$221,D10)/SUMIFS($G$2:$G$221,$C$2:$C$221,C10,$D$2:$D$221,D10),"")) | K10: =IF(COUNTIFS(POLICY_PARAMETERS!$B$2:$B$13,"g",POLICY_PARAMETERS!$E$2:$E$13,C10,POLICY_PARAMETERS!$F$2:$F$13,D10,POLICY_PARAMETERS!$G$2:$G$13,"<>")=0,"",SUMIFS(POLICY_PARAMETERS!$G$2:$G$13,POLICY_PARAMETERS!$B$2:$B$13,"g",POLICY_PARAMETERS!$E$2:$E$13,C10,POLICY_PARAMETERS!$F$2:$F$13,D10)) | L10: =IF(COUNTIFS(POLICY_PARAMETERS!$B$2:$B$13,"r",POLICY_PARAMETERS!$E$2:$E$13,C10,POLICY_PARAMETERS!$F$2:$F$13,D10,POLICY_PARAMETERS!$G$2:$G$13,"<>")=0,"",SUMIFS(POLICY_PARAMETERS!$G$2:$G$13,POLICY_PARAMETERS!$B$2:$B$13,"r",POLICY_PARAMETERS!$E$2:$E$13,C10,POLICY_PARAMETERS!$F$2:$F$13,D10)) | M10: =IF(OR(K10="",L10=""),"",(1+K10)*(1-L10)) | N10: =IF(OR(G10="",J10="",M10=""),"",G10*J10*M10) | O10: =IF(D10=2025,IFERROR(VLOOKUP(A10,OFFICIAL_ALLOCATIONS!$A$2:$F$111,5,FALSE),""),IFERROR(VLOOKUP(A10,OFFICIAL_ALLOCATIONS!$A$2:$F$111,6,FALSE),"")) -> 3585092 | P10: =IF(OR(N10="",O10=""),"",N10-O10) | Q10: =IF(OR(P10="",O10=0),"",P10/O10) | R10: =IF(OR(G10="",H10=""),"MISSING HISTORICAL DATA",IF(I10<>"COMPLETE","INCOMPLETE SECTOR DATA",IF(OR(K10="",L10=""),"MISSING VERIFIED g/r",IF(N10="","NOT READY","READY")))) -> MISSING HISTORICAL DATA | S10: Appendix I, Method No. 01 | T10: https://datafiles.chinhphu.vn/cpp/files/vbpq/2025/6/10-vbhn-bnnmt-kem.pdf
A11: F005 | B11: Công ty Nhiệt điện Cẩm Phả - TKV | C11: Thermal power | D11: 2026 | E11: =D11-3 -> 2023 | F11: =D11-1 -> 2025 | G11: =IF(COUNTIFS(HISTORICAL_DATA!$A$2:$A$441,$A11,HISTORICAL_DATA!$D$2:$D$441,">="&$E11,HISTORICAL_DATA!$D$2:$D$441,"<="&$F11,HISTORICAL_DATA!$E$2:$E$441,"<>")<3,"",SUMIFS(HISTORICAL_DATA!$E$2:$E$441,HISTORICAL_DATA!$A$2:$A$441,$A11,HISTORICAL_DATA!$D$2:$D$441,">="&$E11,HISTORICAL_DATA!$D$2:$D$441,"<="&$F11)/3) | H11: =IF(COUNTIFS(HISTORICAL_DATA!$A$2:$A$441,$A11,HISTORICAL_DATA!$D$2:$D$441,">="&$E11,HISTORICAL_DATA!$D$2:$D$441,"<="&$F11,HISTORICAL_DATA!$G$2:$G$441,"<>")<3,"",SUMIFS(HISTORICAL_DATA!$G$2:$G$441,HISTORICAL_DATA!$A$2:$A$441,$A11,HISTORICAL_DATA!$D$2:$D$441,">="&$E11,HISTORICAL_DATA!$D$2:$D$441,"<="&$F11)/3) | I11: =IF(OR(G11="",H11=""),"FACILITY DATA MISSING",IF(AND(COUNTIFS($C$2:$C$221,C11,$D$2:$D$221,D11,$G$2:$G$221,"<>")=COUNTIF(OFFICIAL_ALLOCATIONS!$C$2:$C$111,C11),COUNTIFS($C$2:$C$221,C11,$D$2:$D$221,D11,$H$2:$H$221,"<>")=COUNTIF(OFFICIAL_ALLOCATIONS!$C$2:$C$111,C11)),"COMPLETE","SECTOR DATA INCOMPLETE")) -> FACILITY DATA MISSING | J11: =IF(I11<>"COMPLETE","",IFERROR(SUMIFS($H$2:$H$221,$C$2:$C$221,C11,$D$2:$D$221,D11)/SUMIFS($G$2:$G$221,$C$2:$C$221,C11,$D$2:$D$221,D11),"")) | K11: =IF(COUNTIFS(POLICY_PARAMETERS!$B$2:$B$13,"g",POLICY_PARAMETERS!$E$2:$E$13,C11,POLICY_PARAMETERS!$F$2:$F$13,D11,POLICY_PARAMETERS!$G$2:$G$13,"<>")=0,"",SUMIFS(POLICY_PARAMETERS!$G$2:$G$13,POLICY_PARAMETERS!$B$2:$B$13,"g",POLICY_PARAMETERS!$E$2:$E$13,C11,POLICY_PARAMETERS!$F$2:$F$13,D11)) | L11: =IF(COUNTIFS(POLICY_PARAMETERS!$B$2:$B$13,"r",POLICY_PARAMETERS!$E$2:$E$13,C11,POLICY_PARAMETERS!$F$2:$F$13,D11,POLICY_PARAMETERS!$G$2:$G$13,"<>")=0,"",SUMIFS(POLICY_PARAMETERS!$G$2:$G$13,POLICY_PARAMETERS!$B$2:$B$13,"r",POLICY_PARAMETERS!$E$2:$E$13,C11,POLICY_PARAMETERS!$F$2:$F$13,D11)) | M11: =IF(OR(K11="",L11=""),"",(1+K11)*(1-L11)) | N11: =IF(OR(G11="",J11="",M11=""),"",G11*J11*M11) | O11: =IF(D11=2025,IFERROR(VLOOKUP(A11,OFFICIAL_ALLOCATIONS!$A$2:$F$111,5,FALSE),""),IFERROR(VLOOKUP(A11,OFFICIAL_ALLOCATIONS!$A$2:$F$111,6,FALSE),"")) -> 3927575 | P11: =IF(OR(N11="",O11=""),"",N11-O11) | Q11: =IF(OR(P11="",O11=0),"",P11/O11) | R11: =IF(OR(G11="",H11=""),"MISSING HISTORICAL DATA",IF(I11<>"COMPLETE","INCOMPLETE SECTOR DATA",IF(OR(K11="",L11=""),"MISSING VERIFIED g/r",IF(N11="","NOT READY","READY")))) -> MISSING HISTORICAL DATA | S11: Appendix I, Method No. 01 | T11: https://datafiles.chinhphu.vn/cpp/files/vbpq/2025/6/10-vbhn-bnnmt-kem.pdf
A12: F006 | B12: Công ty TNHH Điện Lực AES Mông Dương - Nhà máy nhiệt điện Mông Dương II | C12: Thermal power | D12: 2025 | E12: =D12-3 -> 2022 | F12: =D12-1 -> 2024 | G12: =IF(COUNTIFS(HISTORICAL_DATA!$A$2:$A$441,$A12,HISTORICAL_DATA!$D$2:$D$441,">="&$E12,HISTORICAL_DATA!$D$2:$D$441,"<="&$F12,HISTORICAL_DATA!$E$2:$E$441,"<>")<3,"",SUMIFS(HISTORICAL_DATA!$E$2:$E$441,HISTORICAL_DATA!$A$2:$A$441,$A12,HISTORICAL_DATA!$D$2:$D$441,">="&$E12,HISTORICAL_DATA!$D$2:$D$441,"<="&$F12)/3) | H12: =IF(COUNTIFS(HISTORICAL_DATA!$A$2:$A$441,$A12,HISTORICAL_DATA!$D$2:$D$441,">="&$E12,HISTORICAL_DATA!$D$2:$D$441,"<="&$F12,HISTORICAL_DATA!$G$2:$G$441,"<>")<3,"",SUMIFS(HISTORICAL_DATA!$G$2:$G$441,HISTORICAL_DATA!$A$2:$A$441,$A12,HISTORICAL_DATA!$D$2:$D$441,">="&$E12,HISTORICAL_DATA!$D$2:$D$441,"<="&$F12)/3) | I12: =IF(OR(G12="",H12=""),"FACILITY DATA MISSING",IF(AND(COUNTIFS($C$2:$C$221,C12,$D$2:$D$221,D12,$G$2:$G$221,"<>")=COUNTIF(OFFICIAL_ALLOCATIONS!$C$2:$C$111,C12),COUNTIFS($C$2:$C$221,C12,$D$2:$D$221,D12,$H$2:$H$221,"<>")=COUNTIF(OFFICIAL_ALLOCATIONS!$C$2:$C$111,C12)),"COMPLETE","SECTOR DATA INCOMPLETE")) -> FACILITY DATA MISSING | J12: =IF(I12<>"COMPLETE","",IFERROR(SUMIFS($H$2:$H$221,$C$2:$C$221,C12,$D$2:$D$221,D12)/SUMIFS($G$2:$G$221,$C$2:$C$221,C12,$D$2:$D$221,D12),"")) | K12: =IF(COUNTIFS(POLICY_PARAMETERS!$B$2:$B$13,"g",POLICY_PARAMETERS!$E$2:$E$13,C12,POLICY_PARAMETERS!$F$2:$F$13,D12,POLICY_PARAMETERS!$G$2:$G$13,"<>")=0,"",SUMIFS(POLICY_PARAMETERS!$G$2:$G$13,POLICY_PARAMETERS!$B$2:$B$13,"g",POLICY_PARAMETERS!$E$2:$E$13,C12,POLICY_PARAMETERS!$F$2:$F$13,D12)) | L12: =IF(COUNTIFS(POLICY_PARAMETERS!$B$2:$B$13,"r",POLICY_PARAMETERS!$E$2:$E$13,C12,POLICY_PARAMETERS!$F$2:$F$13,D12,POLICY_PARAMETERS!$G$2:$G$13,"<>")=0,"",SUMIFS(POLICY_PARAMETERS!$G$2:$G$13,POLICY_PARAMETERS!$B$2:$B$13,"r",POLICY_PARAMETERS!$E$2:$E$13,C12,POLICY_PARAMETERS!$F$2:$F$13,D12)) | M12: =IF(OR(K12="",L12=""),"",(1+K12)*(1-L12)) | N12: =IF(OR(G12="",J12="",M12=""),"",G12*J12*M12) | O12: =IF(D12=2025,IFERROR(VLOOKUP(A12,OFFICIAL_ALLOCATIONS!$A$2:$F$111,5,FALSE),""),IFERROR(VLOOKUP(A12,OFFICIAL_ALLOCATIONS!$A$2:$F$111,6,FALSE),"")) -> 12190431 | P12: =IF(OR(N12="",O12=""),"",N12-O12) | Q12: =IF(OR(P12="",O12=0),"",P12/O12) | R12: =IF(OR(G12="",H12=""),"MISSING HISTORICAL DATA",IF(I12<>"COMPLETE","INCOMPLETE SECTOR DATA",IF(OR(K12="",L12=""),"MISSING VERIFIED g/r",IF(N12="","NOT READY","READY")))) -> MISSING HISTORICAL DATA | S12: Appendix I, Method No. 01 | T12: https://datafiles.chinhphu.vn/cpp/files/vbpq/2025/6/10-vbhn-bnnmt-kem.pdf
A13: F006 | B13: Công ty TNHH Điện Lực AES Mông Dương - Nhà máy nhiệt điện Mông Dương II | C13: Thermal power | D13: 2026 | E13: =D13-3 -> 2023 | F13: =D13-1 -> 2025 | G13: =IF(COUNTIFS(HISTORICAL_DATA!$A$2:$A$441,$A13,HISTORICAL_DATA!$D$2:$D$441,">="&$E13,HISTORICAL_DATA!$D$2:$D$441,"<="&$F13,HISTORICAL_DATA!$E$2:$E$441,"<>")<3,"",SUMIFS(HISTORICAL_DATA!$E$2:$E$441,HISTORICAL_DATA!$A$2:$A$441,$A13,HISTORICAL_DATA!$D$2:$D$441,">="&$E13,HISTORICAL_DATA!$D$2:$D$441,"<="&$F13)/3) | H13: =IF(COUNTIFS(HISTORICAL_DATA!$A$2:$A$441,$A13,HISTORICAL_DATA!$D$2:$D$441,">="&$E13,HISTORICAL_DATA!$D$2:$D$441,"<="&$F13,HISTORICAL_DATA!$G$2:$G$441,"<>")<3,"",SUMIFS(HISTORICAL_DATA!$G$2:$G$441,HISTORICAL_DATA!$A$2:$A$441,$A13,HISTORICAL_DATA!$D$2:$D$441,">="&$E13,HISTORICAL_DATA!$D$2:$D$441,"<="&$F13)/3) | I13: =IF(OR(G13="",H13=""),"FACILITY DATA MISSING",IF(AND(COUNTIFS($C$2:$C$221,C13,$D$2:$D$221,D13,$G$2:$G$221,"<>")=COUNTIF(OFFICIAL_ALLOCATIONS!$C$2:$C$111,C13),COUNTIFS($C$2:$C$221,C13,$D$2:$D$221,D13,$H$2:$H$221,"<>")=COUNTIF(OFFICIAL_ALLOCATIONS!$C$2:$C$111,C13)),"COMPLETE","SECTOR DATA INCOMPLETE")) -> FACILITY DATA MISSING | J13: =IF(I13<>"COMPLETE","",IFERROR(SUMIFS($H$2:$H$221,$C$2:$C$221,C13,$D$2:$D$221,D13)/SUMIFS($G$2:$G$221,$C$2:$C$221,C13,$D$2:$D$221,D13),"")) | K13: =IF(COUNTIFS(POLICY_PARAMETERS!$B$2:$B$13,"g",POLICY_PARAMETERS!$E$2:$E$13,C13,POLICY_PARAMETERS!$F$2:$F$13,D13,POLICY_PARAMETERS!$G$2:$G$13,"<>")=0,"",SUMIFS(POLICY_PARAMETERS!$G$2:$G$13,POLICY_PARAMETERS!$B$2:$B$13,"g",POLICY_PARAMETERS!$E$2:$E$13,C13,POLICY_PARAMETERS!$F$2:$F$13,D13)) | L13: =IF(COUNTIFS(POLICY_PARAMETERS!$B$2:$B$13,"r",POLICY_PARAMETERS!$E$2:$E$13,C13,POLICY_PARAMETERS!$F$2:$F$13,D13,POLICY_PARAMETERS!$G$2:$G$13,"<>")=0,"",SUMIFS(POLICY_PARAMETERS!$G$2:$G$13,POLICY_PARAMETERS!$B$2:$B$13,"r",POLICY_PARAMETERS!$E$2:$E$13,C13,POLICY_PARAMETERS!$F$2:$F$13,D13)) | M13: =IF(OR(K13="",L13=""),"",(1+K13)*(1-L13)) | N13: =IF(OR(G13="",J13="",M13=""),"",G13*J13*M13) | O13: =IF(D13=2025,IFERROR(VLOOKUP(A13,OFFICIAL_ALLOCATIONS!$A$2:$F$111,5,FALSE),""),IFERROR(VLOOKUP(A13,OFFICIAL_ALLOCATIONS!$A$2:$F$111,6,FALSE),"")) -> 13354978 | P13: =IF(OR(N13="",O13=""),"",N13-O13) | Q13: =IF(OR(P13="",O13=0),"",P13/O13) | R13: =IF(OR(G13="",H13=""),"MISSING HISTORICAL DATA",IF(I13<>"COMPLETE","INCOMPLETE SECTOR DATA",IF(OR(K13="",L13=""),"MISSING VERIFIED g/r",IF(N13="","NOT READY","READY")))) -> MISSING HISTORICAL DATA | S13: Appendix I, Method No. 01 | T13: https://datafiles.chinhphu.vn/cpp/files/vbpq/2025/6/10-vbhn-bnnmt-kem.pdf
A14: F007 | B14: Công ty Nhiệt điện Đông Triều - TKV - Nhà máy nhiệt điện Mạo Khê | C14: Thermal power | D14: 2025 | E14: =D14-3 -> 2022 | F14: =D14-1 -> 2024 | G14: =IF(COUNTIFS(HISTORICAL_DATA!$A$2:$A$441,$A14,HISTORICAL_DATA!$D$2:$D$441,">="&$E14,HISTORICAL_DATA!$D$2:$D$441,"<="&$F14,HISTORICAL_DATA!$E$2:$E$441,"<>")<3,"",SUMIFS(HISTORICAL_DATA!$E$2:$E$441,HISTORICAL_DATA!$A$2:$A$441,$A14,HISTORICAL_DATA!$D$2:$D$441,">="&$E14,HISTORICAL_DATA!$D$2:$D$441,"<="&$F14)/3) | H14: =IF(COUNTIFS(HISTORICAL_DATA!$A$2:$A$441,$A14,HISTORICAL_DATA!$D$2:$D$441,">="&$E14,HISTORICAL_DATA!$D$2:$D$441,"<="&$F14,HISTORICAL_DATA!$G$2:$G$441,"<>")<3,"",SUMIFS(HISTORICAL_DATA!$G$2:$G$441,HISTORICAL_DATA!$A$2:$A$441,$A14,HISTORICAL_DATA!$D$2:$D$441,">="&$E14,HISTORICAL_DATA!$D$2:$D$441,"<="&$F14)/3) | I14: =IF(OR(G14="",H14=""),"FACILITY DATA MISSING",IF(AND(COUNTIFS($C$2:$C$221,C14,$D$2:$D$221,D14,$G$2:$G$221,"<>")=COUNTIF(OFFICIAL_ALLOCATIONS!$C$2:$C$111,C14),COUNTIFS($C$2:$C$221,C14,$D$2:$D$221,D14,$H$2:$H$221,"<>")=COUNTIF(OFFICIAL_ALLOCATIONS!$C$2:$C$111,C14)),"COMPLETE","SECTOR DATA INCOMPLETE")) -> FACILITY DATA MISSING | J14: =IF(I14<>"COMPLETE","",IFERROR(SUMIFS($H$2:$H$221,$C$2:$C$221,C14,$D$2:$D$221,D14)/SUMIFS($G$2:$G$221,$C$2:$C$221,C14,$D$2:$D$221,D14),"")) | K14: =IF(COUNTIFS(POLICY_PARAMETERS!$B$2:$B$13,"g",POLICY_PARAMETERS!$E$2:$E$13,C14,POLICY_PARAMETERS!$F$2:$F$13,D14,POLICY_PARAMETERS!$G$2:$G$13,"<>")=0,"",SUMIFS(POLICY_PARAMETERS!$G$2:$G$13,POLICY_PARAMETERS!$B$2:$B$13,"g",POLICY_PARAMETERS!$E$2:$E$13,C14,POLICY_PARAMETERS!$F$2:$F$13,D14)) | L14: =IF(COUNTIFS(POLICY_PARAMETERS!$B$2:$B$13,"r",POLICY_PARAMETERS!$E$2:$E$13,C14,POLICY_PARAMETERS!$F$2:$F$13,D14,POLICY_PARAMETERS!$G$2:$G$13,"<>")=0,"",SUMIFS(POLICY_PARAMETERS!$G$2:$G$13,POLICY_PARAMETERS!$B$2:$B$13,"r",POLICY_PARAMETERS!$E$2:$E$13,C14,POLICY_PARAMETERS!$F$2:$F$13,D14)) | M14: =IF(OR(K14="",L14=""),"",(1+K14)*(1-L14)) | N14: =IF(OR(G14="",J14="",M14=""),"",G14*J14*M14) | O14: =IF(D14=2025,IFERROR(VLOOKUP(A14,OFFICIAL_ALLOCATIONS!$A$2:$F$111,5,FALSE),""),IFERROR(VLOOKUP(A14,OFFICIAL_ALLOCATIONS!$A$2:$F$111,6,FALSE),"")) -> 4436759 | P14: =IF(OR(N14="",O14=""),"",N14-O14) | Q14: =IF(OR(P14="",O14=0),"",P14/O14) | R14: =IF(OR(G14="",H14=""),"MISSING HISTORICAL DATA",IF(I14<>"COMPLETE","INCOMPLETE SECTOR DATA",IF(OR(K14="",L14=""),"MISSING VERIFIED g/r",IF(N14="","NOT READY","READY")))) -> MISSING HISTORICAL DATA | S14: Appendix I, Method No. 01 | T14: https://datafiles.chinhphu.vn/cpp/files/vbpq/2025/6/10-vbhn-bnnmt-kem.pdf
... A221: F110 | B221: Công ty TNHH Duyên Hà, Nhà máy xi măng Duyên Hà | C221: Cement | D221: 2026 | E221: =D221-3 -> 2023 | F221: =D221-1 -> 2025 | G221: =IF(COUNTIFS(HISTORICAL_DATA!$A$2:$A$441,$A221,HISTORICAL_DATA!$D$2:$D$441,">="&$E221,HISTORICAL_DATA!$D$2:$D$441,"<="&$F221,HISTORICAL_DATA!$E$2:$E$441,"<>")<3,"",SUMIFS(HISTORICAL_DATA!$E$2:$E$441,HISTORICAL_DATA!$A$2:$A$441,$A221,HISTORICAL_DATA!$D$2:$D$441,">="&$E221,HISTORICAL_DATA!$D$2:$D$441,"<="&$F221)/3) | H221: =IF(COUNTIFS(HISTORICAL_DATA!$A$2:$A$441,$A221,HISTORICAL_DATA!$D$2:$D$441,">="&$E221,HISTORICAL_DATA!$D$2:$D$441,"<="&$F221,HISTORICAL_DATA!$G$2:$G$441,"<>")<3,"",SUMIFS(HISTORICAL_DATA!$G$2:$G$441,HISTORICAL_DATA!$A$2:$A$441,$A221,HISTORICAL_DATA!$D$2:$D$441,">="&$E221,HISTORICAL_DATA!$D$2:$D$441,"<="&$F221)/3) | I221: =IF(OR(G221="",H221=""),"FACILITY DATA MISSING",IF(AND(COUNTIFS($C$2:$C$221,C221,$D$2:$D$221,D221,$G$2:$G$221,"<>")=COUNTIF(OFFICIAL_ALLOCATIONS!$C$2:$C$111,C221),COUNTIFS($C$2:$C$221,C221,$D$2:$D$221,D221,$H$2:$H$221,"<>")=COUNTIF(OFFICIAL_ALLOCATIONS!$C$2:$C$111,C221)),"COMPLETE","SECTOR DATA INCOMPLETE")) -> FACILITY DATA MISSING | J221: =IF(I221<>"COMPLETE","",IFERROR(SUMIFS($H$2:$H$221,$C$2:$C$221,C221,$D$2:$D$221,D221)/SUMIFS($G$2:$G$221,$C$2:$C$221,C221,$D$2:$D$221,D221),"")) | K221: =IF(COUNTIFS(POLICY_PARAMETERS!$B$2:$B$13,"g",POLICY_PARAMETERS!$E$2:$E$13,C221,POLICY_PARAMETERS!$F$2:$F$13,D221,POLICY_PARAMETERS!$G$2:$G$13,"<>")=0,"",SUMIFS(POLICY_PARAMETERS!$G$2:$G$13,POLICY_PARAMETERS!$B$2:$B$13,"g",POLICY_PARAMETERS!$E$2:$E$13,C221,POLICY_PARAMETERS!$F$2:$F$13,D221)) | L221: =IF(COUNTIFS(POLICY_PARAMETERS!$B$2:$B$13,"r",POLICY_PARAMETERS!$E$2:$E$13,C221,POLICY_PARAMETERS!$F$2:$F$13,D221,POLICY_PARAMETERS!$G$2:$G$13,"<>")=0,"",SUMIFS(POLICY_PARAMETERS!$G$2:$G$13,POLICY_PARAMETERS!$B$2:$B$13,"r",POLICY_PARAMETERS!$E$2:$E$13,C221,POLICY_PARAMETERS!$F$2:$F$13,D221)) | M221: =IF(OR(K221="",L221=""),"",(1+K221)*(1-L221)) | N221: =IF(OR(G221="",J221="",M221=""),"",G221*J221*M221) | O221: =IF(D221=2025,IFERROR(VLOOKUP(A221,OFFICIAL_ALLOCATIONS!$A$2:$F$111,5,FALSE),""),IFERROR(VLOOKUP(A221,OFFICIAL_ALLOCATIONS!$A$2:$F$111,6,FALSE),"")) -> 1448956 | P221: =IF(OR(N221="",O221=""),"",N221-O221) | Q221: =IF(OR(P221="",O221=0),"",P221/O221) | R221: =IF(OR(G221="",H221=""),"MISSING HISTORICAL DATA",IF(I221<>"COMPLETE","INCOMPLETE SECTOR DATA",IF(OR(K221="",L221=""),"MISSING VERIFIED g/r",IF(N221="","NOT READY","READY")))) -> MISSING HISTORICAL DATA | S221: Appendix I, Method No. 01 | T221: https://datafiles.chinhphu.vn/cpp/files/vbpq/2025/6/10-vbhn-bnnmt-kem.pdf

Sheet POLICY_PARAMETERS
A1: Parameter ID | B1: Symbol | C1: Parameter Name (English) | D1: Tên tham số (Tiếng Việt) | E1: Sector | F1: Allocation Year | G1: Value | H1: Unit | I1: Parameter Type | J1: Verification Status | K1: Source | L1: Notes
A2: PP001 | B2: g | C2: Sector growth target | D2: Mục tiêu tăng trưởng của lĩnh vực | E2: Thermal power | F2: 2025 | H2: % | I2: Policy parameter | J2: VALUE NOT ENTERED — source/value not verified in workbook | K2: https://datafiles.chinhphu.vn/cpp/files/vbpq/2025/6/10-vbhn-bnnmt-kem.pdf | L2: Definition is verified under Method No. 01. Do not populate an official value without a citable source.
A3: PP002 | B3: r | C3: Sector GHG reduction target | D3: Mục tiêu giảm phát thải khí nhà kính của lĩnh vực | E3: Thermal power | F3: 2025 | H3: % | I3: Policy parameter | J3: VALUE NOT ENTERED — source/value not verified in workbook | K3: https://datafiles.chinhphu.vn/cpp/files/vbpq/2025/6/10-vbhn-bnnmt-kem.pdf | L3: Definition is verified under Method No. 01. Do not populate an official value without a citable source.
A4: PP003 | B4: g | C4: Sector growth target | D4: Mục tiêu tăng trưởng của lĩnh vực | E4: Thermal power | F4: 2026 | H4: % | I4: Policy parameter | J4: VALUE NOT ENTERED — source/value not verified in workbook | K4: https://datafiles.chinhphu.vn/cpp/files/vbpq/2025/6/10-vbhn-bnnmt-kem.pdf | L4: Definition is verified under Method No. 01. Do not populate an official value without a citable source.
A5: PP004 | B5: r | C5: Sector GHG reduction target | D5: Mục tiêu giảm phát thải khí nhà kính của lĩnh vực | E5: Thermal power | F5: 2026 | H5: % | I5: Policy parameter | J5: VALUE NOT ENTERED — source/value not verified in workbook | K5: https://datafiles.chinhphu.vn/cpp/files/vbpq/2025/6/10-vbhn-bnnmt-kem.pdf | L5: Definition is verified under Method No. 01. Do not populate an official value without a citable source.
A6: PP005 | B6: g | C6: Sector growth target | D6: Mục tiêu tăng trưởng của lĩnh vực | E6: Iron & steel | F6: 2025 | H6: % | I6: Policy parameter | J6: VALUE NOT ENTERED — source/value not verified in workbook | K6: https://datafiles.chinhphu.vn/cpp/files/vbpq/2025/6/10-vbhn-bnnmt-kem.pdf | L6: Definition is verified under Method No. 01. Do not populate an official value without a citable source.
A7: PP006 | B7: r | C7: Sector GHG reduction target | D7: Mục tiêu giảm phát thải khí nhà kính của lĩnh vực | E7: Iron & steel | F7: 2025 | H7: % | I7: Policy parameter | J7: VALUE NOT ENTERED — source/value not verified in workbook | K7: https://datafiles.chinhphu.vn/cpp/files/vbpq/2025/6/10-vbhn-bnnmt-kem.pdf | L7: Definition is verified under Method No. 01. Do not populate an official value without a citable source.
A8: PP007 | B8: g | C8: Sector growth target | D8: Mục tiêu tăng trưởng của lĩnh vực | E8: Iron & steel | F8: 2026 | H8: % | I8: Policy parameter | J8: VALUE NOT ENTERED — source/value not verified in workbook | K8: https://datafiles.chinhphu.vn/cpp/files/vbpq/2025/6/10-vbhn-bnnmt-kem.pdf | L8: Definition is verified under Method No. 01. Do not populate an official value without a citable source.
A9: PP008 | B9: r | C9: Sector GHG reduction target | D9: Mục tiêu giảm phát thải khí nhà kính của lĩnh vực | E9: Iron & steel | F9: 2026 | H9: % | I9: Policy parameter | J9: VALUE NOT ENTERED — source/value not verified in workbook | K9: https://datafiles.chinhphu.vn/cpp/files/vbpq/2025/6/10-vbhn-bnnmt-kem.pdf | L9: Definition is verified under Method No. 01. Do not populate an official value without a citable source.
A10: PP009 | B10: g | C10: Sector growth target | D10: Mục tiêu tăng trưởng của lĩnh vực | E10: Cement | F10: 2025 | H10: % | I10: Policy parameter | J10: VALUE NOT ENTERED — source/value not verified in workbook | K10: https://datafiles.chinhphu.vn/cpp/files/vbpq/2025/6/10-vbhn-bnnmt-kem.pdf | L10: Definition is verified under Method No. 01. Do not populate an official value without a citable source.
A11: PP010 | B11: r | C11: Sector GHG reduction target | D11: Mục tiêu giảm phát thải khí nhà kính của lĩnh vực | E11: Cement | F11: 2025 | H11: % | I11: Policy parameter | J11: VALUE NOT ENTERED — source/value not verified in workbook | K11: https://datafiles.chinhphu.vn/cpp/files/vbpq/2025/6/10-vbhn-bnnmt-kem.pdf | L11: Definition is verified under Method No. 01. Do not populate an official value without a citable source.
A12: PP011 | B12: g | C12: Sector growth target | D12: Mục tiêu tăng trưởng của lĩnh vực | E12: Cement | F12: 2026 | H12: % | I12: Policy parameter | J12: VALUE NOT ENTERED — source/value not verified in workbook | K12: https://datafiles.chinhphu.vn/cpp/files/vbpq/2025/6/10-vbhn-bnnmt-kem.pdf | L12: Definition is verified under Method No. 01. Do not populate an official value without a citable source.
A13: PP012 | B13: r | C13: Sector GHG reduction target | D13: Mục tiêu giảm phát thải khí nhà kính của lĩnh vực | E13: Cement | F13: 2026 | H13: % | I13: Policy parameter | J13: VALUE NOT ENTERED — source/value not verified in workbook | K13: https://datafiles.chinhphu.vn/cpp/files/vbpq/2025/6/10-vbhn-bnnmt-kem.pdf | L13: Definition is verified under Method No. 01. Do not populate an official value without a citable source.

Sheet REGULATORY_SCOPE
A1: Rule ID | B1: Module | C1: Facility Category / Sector | D1: Trigger / Scope | E1: Threshold / Condition | F1: Result if met | G1: Legal Basis | H1: Effective / Time Scope | I1: Source URL | J1: Implementation Note
A2: INV-01 | B2: Inventory | C2: All facilities | D2: Annual GHG emissions | E2: ≥ 3,000 tCO2e/year | F2: Meets inventory criterion | G2: 48/VBHN-BNNMT, Article 6(1) | H2: Current rule | I2: https://datafiles.chinhphu.vn/cpp/files/vbpq/2026/4/48-vbhn-bnnmt.pdf | J2: For a definitive list-based answer, also check the effective Prime Minister inventory list.
A3: INV-02 | B3: Inventory | C3: Thermal power / industrial production | D3: Annual energy consumption | E3: ≥ 1,000 TOE/year | F3: Meets inventory criterion | G3: 48/VBHN-BNNMT, Article 6(1)(a) | H3: Current rule | I3: https://datafiles.chinhphu.vn/cpp/files/vbpq/2026/4/48-vbhn-bnnmt.pdf | J3: Do not apply this energy threshold to unrelated facility categories.
A4: INV-03 | B4: Inventory | C4: Freight transport company | D4: Annual fuel consumption | E4: ≥ 1,000 TOE/year | F4: Meets inventory criterion | G4: 48/VBHN-BNNMT, Article 6(1)(b) | H4: Current rule | I4: https://datafiles.chinhphu.vn/cpp/files/vbpq/2026/4/48-vbhn-bnnmt.pdf | J4: Use fuel consumption in TOE.
A5: INV-04 | B5: Inventory | C5: Commercial building | D5: Annual energy consumption | E5: ≥ 1,000 TOE/year | F5: Meets inventory criterion | G5: 48/VBHN-BNNMT, Article 6(1)(c) | H5: Current rule | I5: https://datafiles.chinhphu.vn/cpp/files/vbpq/2026/4/48-vbhn-bnnmt.pdf | J5: Use annual energy consumption.
A6: INV-05 | B6: Inventory | C6: Solid waste treatment facility | D6: Annual operating capacity | E6: ≥ 65,000 tonnes/year | F6: Meets inventory criterion | G6: 48/VBHN-BNNMT, Article 6(1)(d) | H6: Current rule | I6: https://datafiles.chinhphu.vn/cpp/files/vbpq/2026/4/48-vbhn-bnnmt.pdf | J6: Capacity criterion, not annual emissions.
A7: LIST-13 | B7: Inventory list | C7: All listed facilities | D7: Official list membership | E7: Decision 13/2024/QĐ-TTg | F7: Inventory-list obligation | G7: Decision 13/2024/QĐ-TTg | H7: Effective 01/10/2024 through 24/09/2026 | I7: https://vanban.chinhphu.vn/?classid=1&docid=210939&pageid=27160&typegroupid=5 | J7: As of 13/09/2026 this is the effective inventory list.
A8: LIST-42 | B8: Inventory list | C8: All listed facilities | D8: Official list membership | E8: Decision 42/2026/QĐ-TTg | F8: Inventory-list obligation | G8: Decision 42/2026/QĐ-TTg, Article 3 | H8: Effective from 25/09/2026 | I8: https://vanban.chinhphu.vn/?classid=1&docid=219154&pageid=27160&typegroupid=5 | J8: Replaces Decision 13/2024/QĐ-TTg from its effective date.
A9: ETS-01 | B9: Quota allocation | C9: Thermal power; iron & steel; cement | D9: 2025-2026 pilot scope | E9: Facility must be in the relevant inventory list and be allocated under Decision 699/QĐ-BNNMT | F9: Quota obligation for pilot phase | G9: 48/VBHN-BNNMT, Article 12(1); Decision 699/QĐ-BNNMT | H9: 2025-2026 | I9: https://dcc.mae.gov.vn/Pages/chi-tiet-tin-DCC.aspx?ItemID=3881&cm=0&mn=0 | J9: Inventory obligation alone does not mean the facility has a quota obligation.
A10: ETS-02 | B10: Allocation method | C10: Thermal power | D10: Product basis | E10: Electricity, kWh | F10: Use in P_avg and B | G10: Appendix I, Method No. 01 | H10: 2025-2026 method | I10: https://datafiles.chinhphu.vn/cpp/files/vbpq/2025/6/10-vbhn-bnnmt-kem.pdf | J10: Historical window = y-1, y-2, y-3.
A11: ETS-03 | B11: Allocation method | C11: Iron & steel | D11: Product basis | E11: Crude steel, tonnes | F11: Use in P_avg and B | G11: Appendix I, Method No. 01 | H11: 2025-2026 method | I11: https://datafiles.chinhphu.vn/cpp/files/vbpq/2025/6/10-vbhn-bnnmt-kem.pdf | J11: Historical window = y-1, y-2, y-3.
A12: ETS-04 | B12: Allocation method | C12: Cement | D12: Product basis | E12: Clinker, tonnes | F12: Use in P_avg and B | G12: Appendix I, Method No. 01 | H12: 2025-2026 method | I12: https://datafiles.chinhphu.vn/cpp/files/vbpq/2025/6/10-vbhn-bnnmt-kem.pdf | J12: Historical window = y-1, y-2, y-3.
... A15: COMP-03 | B15: Compliance | C15: Allocated facilities | D15: Borrowing from next phase | E15: ≤ 15% of allowances allocated for current phase | F15: Maximum eligible borrowing | G15: 48/VBHN-BNNMT, Article 19(6) | H15: Through end-2030 | I15: https://datafiles.chinhphu.vn/cpp/files/vbpq/2026/4/48-vbhn-bnnmt.pdf | J15: Borrowed allowances cannot be used for exchange.

Sheet OFFICIAL_ALLOCATIONS
A1: Facility ID | B1: Facility Name | C1: Sector | D1: Tax ID | E1: Official Allocation 2025 (tCO2e) | F1: Official Allocation 2026 (tCO2e) | G1: Legal Source | H1: Data Status | I1: Notes
A2: ="F"&TEXT(ROW()-1,"000") -> F001 | B2: =CLEAN_699!B2 -> Công ty nhiệt điện Na Dương | C2: ="Thermal power" -> Thermal power | D2: =CLEAN_699!D2 -> 0104297034-001 | E2: =CLEAN_699!F2 -> 1035566 | F2: =CLEAN_699!G2 -> 1134493 | G2: ="Decision 699/QĐ-BNNMT" -> Decision 699/QĐ-BNNMT | H2: ="Official" -> Official | I2: ="Official allocation under Decision 699/QĐ-BNNMT" -> Official allocation under Decision 699/QĐ-BNNMT
A3: ="F"&TEXT(ROW()-1,"000") -> F002 | B3: =CLEAN_699!B3 -> Công ty nhiệt điện Sơn động Việt Nam | C3: ="Thermal power" -> Thermal power | D3: =CLEAN_699!D3 -> 0104297034-003 | E3: =CLEAN_699!F3 -> 2032458 | F3: =CLEAN_699!G3 -> 2226618 | G3: ="Decision 699/QĐ-BNNMT" -> Decision 699/QĐ-BNNMT | H3: ="Official" -> Official | I3: ="Official allocation under Decision 699/QĐ-BNNMT" -> Official allocation under Decision 699/QĐ-BNNMT
A4: ="F"&TEXT(ROW()-1,"000") -> F003 | B4: =CLEAN_699!B4 -> Công ty Nhiệt điện Uông Bí | C4: ="Thermal power" -> Thermal power | D4: =CLEAN_699!D4 -> 5701662152-010 | E4: =CLEAN_699!F4 -> 5691098 | F4: =CLEAN_699!G4 -> 6234766 | G4: ="Decision 699/QĐ-BNNMT" -> Decision 699/QĐ-BNNMT | H4: ="Official" -> Official | I4: ="Official allocation under Decision 699/QĐ-BNNMT" -> Official allocation under Decision 699/QĐ-BNNMT
A5: ="F"&TEXT(ROW()-1,"000") -> F004 | B5: =CLEAN_699!B5 -> Công ty Cổ phần Nhiệt điện Quảng Ninh | C5: ="Thermal power" -> Thermal power | D5: =CLEAN_699!D5 -> 5700434869 | E5: =CLEAN_699!F5 -> 11097421 | F5: =CLEAN_699!G5 -> 12157553 | G5: ="Decision 699/QĐ-BNNMT" -> Decision 699/QĐ-BNNMT | H5: ="Official" -> Official | I5: ="Official allocation under Decision 699/QĐ-BNNMT" -> Official allocation under Decision 699/QĐ-BNNMT
A6: ="F"&TEXT(ROW()-1,"000") -> F005 | B6: =CLEAN_699!B6 -> Công ty Nhiệt điện Cẩm Phả - TKV | C6: ="Thermal power" -> Thermal power | D6: =CLEAN_699!D6 -> 0104297034-008 | E6: =CLEAN_699!F6 -> 3585092 | F6: =CLEAN_699!G6 -> 3927575 | G6: ="Decision 699/QĐ-BNNMT" -> Decision 699/QĐ-BNNMT | H6: ="Official" -> Official | I6: ="Official allocation under Decision 699/QĐ-BNNMT" -> Official allocation under Decision 699/QĐ-BNNMT
A7: ="F"&TEXT(ROW()-1,"000") -> F006 | B7: =CLEAN_699!B7 -> Công ty TNHH Điện Lực AES Mông Dương - Nhà máy nhiệt điện Mông Dương II | C7: ="Thermal power" -> Thermal power | D7: =CLEAN_699!D7 -> 5701384498 | E7: =CLEAN_699!F7 -> 12190431 | F7: =CLEAN_699!G7 -> 13354978 | G7: ="Decision 699/QĐ-BNNMT" -> Decision 699/QĐ-BNNMT | H7: ="Official" -> Official | I7: ="Official allocation under Decision 699/QĐ-BNNMT" -> Official allocation under Decision 699/QĐ-BNNMT
A8: ="F"&TEXT(ROW()-1,"000") -> F007 | B8: =CLEAN_699!B8 -> Công ty Nhiệt điện Đông Triều - TKV - Nhà máy nhiệt điện Mạo Khê | C8: ="Thermal power" -> Thermal power | D8: =CLEAN_699!D8 -> 0104297034-006 | E8: =CLEAN_699!F8 -> 4436759 | F8: =CLEAN_699!G8 -> 4860601 | G8: ="Decision 699/QĐ-BNNMT" -> Decision 699/QĐ-BNNMT | H8: ="Official" -> Official | I8: ="Official allocation under Decision 699/QĐ-BNNMT" -> Official allocation under Decision 699/QĐ-BNNMT
A9: ="F"&TEXT(ROW()-1,"000") -> F008 | B9: =CLEAN_699!B9 -> Nhà máy nhiệt điện Mông Dương I - Công ty Nhiệt điện Mông Dương | C9: ="Thermal power" -> Thermal power | D9: =CLEAN_699!D9 -> 3502208399-008 | E9: =CLEAN_699!F9 -> 9556403 | F9: =CLEAN_699!G9 -> 10469322 | G9: ="Decision 699/QĐ-BNNMT" -> Decision 699/QĐ-BNNMT | H9: ="Official" -> Official | I9: ="Official allocation under Decision 699/QĐ-BNNMT" -> Official allocation under Decision 699/QĐ-BNNMT
A10: ="F"&TEXT(ROW()-1,"000") -> F009 | B10: =CLEAN_699!B10 -> Công ty Cổ phần Nhiệt điện Hải Phòng | C10: ="Thermal power" -> Thermal power | D10: =CLEAN_699!D10 -> 200493225 | E10: =CLEAN_699!F10 -> 10239469 | F10: =CLEAN_699!G10 -> 11217642 | G10: ="Decision 699/QĐ-BNNMT" -> Decision 699/QĐ-BNNMT | H10: ="Official" -> Official | I10: ="Official allocation under Decision 699/QĐ-BNNMT" -> Official allocation under Decision 699/QĐ-BNNMT
A11: ="F"&TEXT(ROW()-1,"000") -> F010 | B11: =CLEAN_699!B11 -> Nhà máy điện Nghi Sơn 1 | C11: ="Thermal power" -> Thermal power | D11: =CLEAN_699!D11 -> 5701662152-011 | E11: =CLEAN_699!F11 -> 5036163 | F11: =CLEAN_699!G11 -> 5517266 | G11: ="Decision 699/QĐ-BNNMT" -> Decision 699/QĐ-BNNMT | H11: ="Official" -> Official | I11: ="Official allocation under Decision 699/QĐ-BNNMT" -> Official allocation under Decision 699/QĐ-BNNMT
A12: ="F"&TEXT(ROW()-1,"000") -> F011 | B12: =CLEAN_699!B12 -> Công ty Điện lực Dầu khí Hà Tĩnh | C12: ="Thermal power" -> Thermal power | D12: =CLEAN_699!D12 -> 0102276173-007 | E12: =CLEAN_699!F12 -> 7214687 | F12: =CLEAN_699!G12 -> 7903903 | G12: ="Decision 699/QĐ-BNNMT" -> Decision 699/QĐ-BNNMT | H12: ="Official" -> Official | I12: ="Official allocation under Decision 699/QĐ-BNNMT" -> Official allocation under Decision 699/QĐ-BNNMT
A13: ="F"&TEXT(ROW()-1,"000") -> F012 | B13: =CLEAN_699!B13 -> Công ty TNHH Hưng Nghiệp Formosa | C13: ="Thermal power" -> Thermal power | D13: =CLEAN_699!D13 -> 3600517557 | E13: =CLEAN_699!F13 -> 2558365 | F13: =CLEAN_699!G13 -> 2802764 | G13: ="Decision 699/QĐ-BNNMT" -> Decision 699/QĐ-BNNMT | H13: ="Official" -> Official | I13: ="Official allocation under Decision 699/QĐ-BNNMT" -> Official allocation under Decision 699/QĐ-BNNMT
... A111: ="F"&TEXT(ROW()-1,"000") -> F110 | B111: =CLEAN_699!B111 -> Công ty TNHH Duyên Hà, Nhà máy xi măng Duyên Hà | C111: ="Thermal power" -> Thermal power | D111: =CLEAN_699!D111 -> 0100520789-002 | E111: =CLEAN_699!F111 -> 1324157 | F111: =CLEAN_699!G111 -> 1448956 | G111: ="Decision 699/QĐ-BNNMT" -> Decision 699/QĐ-BNNMT | H111: ="Official" -> Official | I111: ="Official allocation under Decision 699/QĐ-BNNMT" -> Official allocation under Decision 699/QĐ-BNNMT

Sheet RAW_699
A1: STT | B1: Tên cơ sở | C1: Địa chỉ | D1: Mã số thuế | E1: Người đại diện pháp luật | F1: Hạn ngạch 2025 (tCO2e) | G1: Hạn ngạch 2026 (tCO2e)
A2: I | B2: Các nhà máy nhiệt điện
A3: 1 | B3: Công ty nhiệt điện Na Dương | C3: Thị trấn Na Dương, huyện Lộc Bình, tỉnh Lang Sơn | D3: 0104297034-001 | E3: Phạm Đức Tuyên | F3: 1,035,566 | G3: 1,134,493
A4: 2 | B4: Công ty nhiệt điện Sơn động Việt Nam | C4: Thị trấn Tây Yên Tử, huyện Sơn Đông, tỉnh Bắc Giang | D4: 0104297034-003 | E4: Dương Hồng Đường | F4: 2,032,458 | G4: 2,226,618
A5: 3 | B5: Công ty Nhiệt điện Uông Bí | C5: Khu 6, Quang Trung, thành phố Uông Bí, tỉnh Quảng Ninh | D5: 5701662152-010 | E5: Đỗ Trung Kiên | F5: 5,691,098 | G5: 6,234,766
A6: 4 | B6: Công ty Cổ phần Nhiệt điện Quảng Ninh | C6: T33K5, phường Hà Khánh, Hạ Long, tỉnh Quảng Ninh | D6: 5700434869 | E6: Nguyễn Việt Dũng | F6: 11,097,421 | G6: 12,157,553
A7: 5 | B7: Công ty Nhiệt điện Cẩm Phả - TKV | C7: Tổ 4, khu 4A, Phường Cẩm Thịnh, Cẩm Phả, tỉnh Quảng Ninh | D7: 0104297034-008 | E7: Trần Văn Hoan | F7: 3,585,092 | G7: 3,927,575
A8: 6 | B8: Công ty TNHH Điện Lực AES Mông Dương - Nhà máy nhiệt điện Mông Dương II | C8: Khu 8, phường Mông Dương, Cẩm Phả, tỉnh Quảng Ninh | D8: 5701384498 | E8: Oliver Robert Jean Marquette | F8: 12,190,431 | G8: 13,354,978
